Workbook

Sheet Planilha1
A1: Nome do vendedor 1 | B1: (Tudo)
A2: Categoria | B2: (Tudo)
A3: Loja | B3: (Tudo)
A5: Rótulos de Linha | B5: Soma de Quantidade Faturada | C5: Soma de Total Vendas
A6: INOC. NODUSOJA BIOLYC L - 3 LT 7,5X10E9 UFC/ML | B6: 2208 | C6: 65809.44
A7: INOC. NODUSOJA ELKANI - 3 LT | B7: 2424 | C7: 90510
A8: INOC. NODUSOJA L - 3 LT 6X10E9 UFC/ML | B8: 1740 | C8: 40891.212
A9: INOC. NODUSOJA NODUBEANS L FEIJAO 3 LT | B9: 24 | C9: 1296
A10: INOC. NODUSOJA REND+ 3 LT | B10: 3132 | C10: 67839.12
A11: INOC. NODUSOJA TURFOSO - 0,8 GR 6X10E9 UFC/G | B11: 979.2 | C11: 24732
A12: INOCULANTE LALFIX NITRO - 3 LT 1X10E10 UFC/ML | B12: 9108 | C12: 360562.06
A13: INOCULANTE NITROSPHERA AMENDOIM - 1,5 LT | B13: 288 | C13: 14400
A14: INOCULANTE STARFIX SOJA - 3 LT 1X10E10 UFC/ML | B14: 53307 | C14: 1960199.2
A15: Total Geral | B15: 73210.2 | C15: 2626239

Sheet Carlos Alves
A1: Nome do vendedor 1 | B1: CARLOS WILSON FERREIRA ALVES
A2: Categoria | B2: Lallemand
A3: Loja | B3: Sinop
A5: Rótulos de Linha | B5: Soma de Quantidade Faturada | C5: Soma de Total Vendas
A6: AGENOR VICENTE PELISSA | B6: 1782 | C6: 308850
A7: CRYSTAL - 1 LT | B7: 450 | C7: 15750
A8: LALSTOP ORGANIC WP - 1 KG | B8: 852 | C8: 149100
A9: ONIX OG - 1 LT | B9: 240 | C9: 72000
A10: RIZOS OG - 1 LT | B10: 240 | C10: 72000
A11: ALERI LUIZ CANAN | B11: 304 | C11: 42036
A12: LALRISE AZOS - AZ39 3L | B12: 114 | C12: 5130
A13: LALSTOP ORGANIC WP - 1 KG | B13: 184 | C13: 34776
A14: ONIX OG - 1 LT | B14: 3 | C14: 1065
A15: RIZOS OG - 1 LT | B15: 3 | C15: 1065
A16: ANDREI DIETRICH | B16: 835 | C16: 80292
A17: CRYSTAL - 1 LT | B17: 300 | C17: 15000
... A164: Total Geral | B164: 22214 | C164: 3078121.8
A166: Rótulos de Linha | B166: Soma de Quantidade Faturada
A167: CRYSTAL - 1 LT | B167: 3915
A168: CRYSTAL - 5 LT | B168: 880
A169: INOCULANTE STARFIX SOJA - 3 LT 1X10E10 UFC/ML | B169: 4347
A170: LALGUARD C99 WP (BR) - 1 KG | B170: 213
A171: LALNIX RESIST - 1 KG | B171: 474
A172: LALRISE AZOS - AZ39 3L | B172: 3024
A173: LALSTOP ORGANIC WP - 1 KG | B173: 5156
A174: ONIX OG - 1 LT | B174: 2388
A175: QUALITY WG - 1 KG | B175: 332
A176: RIZOS OG - 1 LT | B176: 1485
A177: Total Geral | B177: 22214
A179: Rótulos de Linha | B179: Soma de Quantidade Faturada | C179: Soma de Total Vendas
A180: AGENOR VICENTE PELISSA | B180: 160 | C180: 156000
A181: VERDIVO ELYSIAN 1 LT | B181: 160 | C181: 156000
A182: ALERI LUIZ CANAN | B182: 16 | C182: 2960
A183: VERDIVO OFF ESPUMA 1 LT | B183: 16 | C183: 2960
A184: ANGELA MARIA BEAL | B184: 115 | C184: 21850
A185: VERDIVO STAND 5 LT | B185: 115 | C185: 21850
A186: ARIOLANDO BORGES DE RESENDE E OUTROS | B186: 100 | C186: 1200
A187: ZOM OLEO MINERAL 20 LT | B187: 100 | C187: 1200
A188: ELIO SAUER | B188: 600 | C188: 12900
A189: VERDIVO PRODUTIVO MZ 10 KG | B189: 600 | C189: 12900
...

Sheet Planilha5
A1: CLIENTE | B1: PRODUTO | C1: VOLUME
A2: AGENOR VICENTE PELISSA | B2: CRYSTAL - 1 LT | C2: =VLOOKUP(Planilha5!B2,'Carteira Pedidos de Venda - 202'!I:Q,10,TRUE) -> #N/A
A3: AGENOR VICENTE PELISSA | B3: CRYSTAL - 5 LT | C3: =VLOOKUP(Planilha5!B3,'Carteira Pedidos de Venda - 202'!I:Q,10,TRUE) -> #N/A
A4: AGENOR VICENTE PELISSA | B4: INOCULANTE LALFIX NITRO - 3 LT 1X10E10 UFC/ML | C4: =VLOOKUP(Planilha5!B4,'Carteira Pedidos de Venda - 202'!I:Q,10,TRUE) -> #REF!
A5: AGENOR VICENTE PELISSA | B5: INOCULANTE STARFIX SOJA - 3 LT 1X10E10 UFC/ML | C5: =VLOOKUP(Planilha5!B5,'Carteira Pedidos de Venda - 202'!I:Q,10,TRUE) -> #REF!
A6: AGENOR VICENTE PELISSA | B6: LALGUARD C99 WP (BR) - 1 KG | C6: =VLOOKUP(Planilha5!B6,'Carteira Pedidos de Venda - 202'!I:Q,10,TRUE) -> #REF!
A7: AGENOR VICENTE PELISSA | B7: LALNIX RESIST - 1 KG | C7: =VLOOKUP(Planilha5!B7,'Carteira Pedidos de Venda - 202'!I:Q,10,TRUE) -> #REF!
A8: AGENOR VICENTE PELISSA | B8: LALRISE AZOS - AZ39 3L | C8: =VLOOKUP(Planilha5!B8,'Carteira Pedidos de Venda - 202'!I:Q,10,TRUE) -> #REF!
A9: AGENOR VICENTE PELISSA | B9: LALSTIM NUTRI 20LT | C9: =VLOOKUP(Planilha5!B9,'Carteira Pedidos de Venda - 202'!I:Q,10,TRUE) -> #REF!
A10: AGENOR VICENTE PELISSA | B10: LALSTOP ORGANIC WP - 1 KG | C10: =VLOOKUP(Planilha5!B10,'Carteira Pedidos de Venda - 202'!I:Q,10,TRUE) -> #REF!
A11: AGENOR VICENTE PELISSA | B11: ONIX OG - 1 LT | C11: =VLOOKUP(Planilha5!B11,'Carteira Pedidos de Venda - 202'!I:Q,10,TRUE) -> #REF!
A12: AGENOR VICENTE PELISSA | B12: QUALITY WG - 1 KG | C12: =VLOOKUP(Planilha5!B12,'Carteira Pedidos de Venda - 202'!I:Q,10,TRUE) -> #REF!
A13: AGENOR VICENTE PELISSA | B13: RIZOS OG - 1 LT | C13: =VLOOKUP(Planilha5!B13,'Carteira Pedidos de Venda - 202'!I:Q,10,TRUE) -> #REF!
... A21: AGENOR VICENTE PELISSA | B21: VERDIVO DROP GUARD 1L | C21: =VLOOKUP(Planilha5!B21,'Carteira Pedidos de Venda - 202'!I:Q,10,TRUE) -> #REF!
B22: VERDIVO DROP GUARD 5L | C22: =VLOOKUP(Planilha5!B22,'Carteira Pedidos de Venda - 202'!I:Q,10,TRUE) -> #REF!
B23: VERDIVO ELYSIAN 1 LT | C23: =VLOOKUP(Planilha5!B23,'Carteira Pedidos de Venda - 202'!I:Q,10,TRUE) -> #REF!
B24: VERDIVO ELYVER 10 LT
B25: VERDIVO EXACT 1 LT
B26: VERDIVO EXACT 5 LT
B27: VERDIVO FIX COMONI 20 LT
B28: VERDIVO MAGLEAF 20 LT
B29: VERDIVO MN ACTION 20 LT
B30: VERDIVO MN EDTA 10 KG
B31: VERDIVO NITRATO DE K 25KG
B32: VERDIVO NITROVERD IBC 1.000 LT
B33: VERDIVO OFF ESPUMA 1 LT
B34: VERDIVO PHOTOMIX 10KG
B35: VERDIVO POTENZA K 10 KG
... B40: VERDIVO VERDMAX 20L

Sheet Meta Lallemand Sinop 
A1: Rótulos de Linha | B1: Soma de Quantidade Faturada | C1: 26/27 | D1: %
A2: CRYSTAL - 1 LT | B2: 3915 | C2: 4500 | D2: =(1-(B2/C2))*100 -> 13
A3: CRYSTAL - 5 LT | B3: 880 | D3: =(1-(B3/C3))*100 -> #DIV/0!
A4: INOCULANTE LALFIX NITRO - 3 LT 1X10E10 UFC/ML | B4: 3894 | C4: 3000 | D4: =(1-(B4/C4))*100 -> -29.8
A5: INOCULANTE STARFIX SOJA - 3 LT 1X10E10 UFC/ML | B5: 10941 | C5: 16503 | D5: =(1-(B5/C5))*100 -> 33.702963
A6: LALGUARD C99 WP (BR) - 1 KG | B6: 1313 | C6: 5200 | D6: =(1-(B6/C6))*100 -> 74.75
A7: LALNIX RESIST - 1 KG | B7: 774 | C7: 1000 | D7: =(1-(B7/C7))*100 -> 22.6
A8: LALRISE AZOS - AZ39 3L | B8: 10569 | C8: 12060 | D8: =(1-(B8/C8))*100 -> 12.363184
A9: LALSTIM NUTRI 20LT | B9: 4000 | C9: 10000 | D9: =(1-(B9/C9))*100 -> 60
A10: LALSTOP ORGANIC WP - 1 KG | B10: 6811 | C10: 4300 | D10: =(1-(B10/C10))*100 -> -58.395349
A11: ONIX OG - 1 LT | B11: 5575 | C11: 4100 | D11: =(1-(B11/C11))*100 -> -35.97561
A12: QUALITY WG - 1 KG | B12: 2595 | C12: 2300 | D12: =(1-(B12/C12))*100 -> -12.826087
A13: RIZOS OG - 1 LT | B13: 4761 | C13: 3100 | D13: =(1-(B13/C13))*100 -> -53.580645
A14: Total Geral | B14: 56028

Sheet Planilha3
A1: Rótulos de Linha | B1: Soma de Quantidade Faturada | C1: 26/27 | D1: %
A2: BIOPROTECTOR - 3L | B2: 1551
A3: CRYSTAL - 1 LT | B3: 1420 | C3: 8500 | D3: =(1-(B3/C3))*100 -> 83.294118
A4: CRYSTAL - 5 LT | B4: 75
A5: INOCULANTE LALFIX NITRO - 3 LT 1X10E10 UFC/ML | B5: 5214 | C5: 6000 | D5: =(1-(B5/C5))*100 -> 13.1
A6: INOCULANTE STARFIX SOJA - 3 LT 1X10E10 UFC/ML | B6: 42366 | C6: 320001 | D6: =(1-(B6/C6))*100 -> 86.760666
A7: LALGUARD C99 WP (BR) - 1 KG | B7: 8660 | C7: 11700 | D7: =(1-(B7/C7))*100 -> 25.982906
A8: LALNIX RESIST - 1 KG | B8: 1192 | C8: 1800 | D8: =(1-(B8/C8))*100 -> 33.777778
A9: LALRISE AZOS - AZ39 3L | B9: 28680 | C9: 33198 | D9: =(1-(B9/C9))*100 -> 13.609254
A10: LALSTIM NUTRI 20LT | B10: 22680 | C10: 40000 | D10: =(1-(B10/C10))*100 -> 43.3
A11: LALSTOP ORGANIC WP - 1 KG | B11: 13045 | C11: 10800 | D11: =(1-(B11/C11))*100 -> -20.787037
A12: ONIX OG - 1 LT | B12: 11880 | C12: 8100 | D12: =(1-(B12/C12))*100 -> -46.666667
A13: ONIX OG - 5 LT | B13: 80
A14: QUALITY WG - 1 KG | B14: 10623 | C14: 6200 | D14: =(1-(B14/C14))*100 -> -71.33871
A15: RIZOS OG - 1 LT | B15: 10772 | C15: 6300 | D15: =(1-(B15/C15))*100 -> -70.984127
A16: RIZOS OG - 5 LT | B16: 80
A17: Total Geral | B17: 158318

Sheet Carteira Pedidos de Venda - 202
A1: Data da inserção | B1: Código do pedido de venda | C1: Razão social | D1: Réplica da data de emissão do pedido | E1: Data do vencimento do pedido | F1: Nome do vendedor 1 | G1: Loja | H1: Código do CFO | I1: Descrição do produto/serviço | J1: Categoria | K1: Unidade de medida | L1: Valor líquido do item (feito os rateios dos valores do fechamento do pedido) | M1: Número do pedido de origem | N1: Descrição Ciclo | O1: Quantidade pedida | P1: Quantidade entrada | Q1: Quantidade Faturada | R1: Total Vendas | S1: Vencimento da parcela | T1: MUNIPRO | U1: CGC_TRA | V1: VLOR_IPE | W1: QPER_IPE
A2: 45880.352 | B2: 3973 | C2: AA AGRONEGOCIOS LTDA | D2: 45880 | E2: 46142 | F2: PEDRO FILIPE COELHO MAGALHAES | H2: 510200 | I2: VERDIVO MN ACTION 20 LT | J2: Verdivo | K2: LT | L2: 18 | M2: 5532 | N2: SAFRA 25/26 | O2: 700 | P2: 0 | Q2: 700 | R2: =Q2*L2 -> 12600 | T2: NOVA UBIRATA | U2: 42652916000176 | V2: 18 | W2: 0
A3: 45880.352 | B3: 3973 | C3: AA AGRONEGOCIOS LTDA | D3: 45880 | E3: 46142 | F3: PEDRO FILIPE COELHO MAGALHAES | H3: 510200 | I3: VERDIVO FIX COMONI 20 LT | J3: Verdivo | K3: LT | L3: 160 | M3: 5532 | N3: SAFRA 25/26 | O3: 140 | P3: 0 | Q3: 140 | R3: =Q3*L3 -> 22400 | T3: NOVA UBIRATA | U3: 42652916000176 | V3: 160 | W3: 0
A4: 45880.352 | B4: 3973 | C4: AA AGRONEGOCIOS LTDA | D4: 45880 | E4: 46142 | F4: PEDRO FILIPE COELHO MAGALHAES | H4: 510200 | I4: VERDIVO PRODUTIVO MZ 10 KG | J4: Verdivo | K4: KG | L4: 23.5 | M4: 5532 | N4: SAFRA 25/26 | O4: 1410 | P4: 0 | Q4: 1410 | R4: =Q4*L4 -> 33135 | T4: NOVA UBIRATA | U4: 42652916000176 | V4: 23.5 | W4: 0
A5: 45880.352 | B5: 3973 | C5: AA AGRONEGOCIOS LTDA | D5: 45880 | E5: 46142 | F5: PEDRO FILIPE COELHO MAGALHAES | H5: 510200 | I5: VERDIVO VERDMAX 20L | J5: Verdivo | K5: LT | L5: 25 | M5: 5532 | N5: SAFRA 25/26 | O5: 700 | P5: 0 | Q5: 700 | R5: =Q5*L5 -> 17500 | T5: NOVA UBIRATA | U5: 42652916000176 | V5: 25 | W5: 0
A6: 45880.352 | B6: 3973 | C6: AA AGRONEGOCIOS LTDA | D6: 45880 | E6: 46142 | F6: PEDRO FILIPE COELHO MAGALHAES | H6: 510200 | I6: VERDIVO BOROFORCE - 10 KG | J6: Verdivo | K6: KG | L6: 28 | M6: 5532 | N6: SAFRA 25/26 | O6: 1770 | P6: 0 | Q6: 1770 | R6: =Q6*L6 -> 49560 | T6: NOVA UBIRATA | U6: 42652916000176 | V6: 28 | W6: 0
A7: 45880.352 | B7: 3973 | C7: AA AGRONEGOCIOS LTDA | D7: 45880 | E7: 46142 | F7: PEDRO FILIPE COELHO MAGALHAES | H7: 510200 | I7: VERDIVO POTENZA K 10 KG | J7: Verdivo | K7: KG | L7: 25 | M7: 5532 | N7: SAFRA 25/26 | O7: 1060 | P7: 0 | Q7: 1060 | R7: =Q7*L7 -> 26500 | T7: NOVA UBIRATA | U7: 42652916000176 | V7: 25 | W7: 0
A8: 45880.352 | B8: 3973 | C8: AA AGRONEGOCIOS LTDA | D8: 45880 | E8: 46142 | F8: PEDRO FILIPE COELHO MAGALHAES | H8: 510200 | I8: VERDIVO EXACT 5 LT | J8: Verdivo | K8: LT | L8: 75 | M8: 5532 | N8: SAFRA 25/26 | O8: 140 | P8: 0 | Q8: 140 | R8: =Q8*L8 -> 10500 | T8: NOVA UBIRATA | U8: 42652916000176 | V8: 75 | W8: 0
A9: 45880.352 | B9: 3973 | C9: AA AGRONEGOCIOS LTDA | D9: 45880 | E9: 46142 | F9: PEDRO FILIPE COELHO MAGALHAES | H9: 510200 | I9: VERDIVO ATTACK SPRAY 5 LT | J9: Verdivo | K9: LT | L9: 75 | M9: 5532 | N9: SAFRA 25/26 | O9: 105 | P9: 0 | Q9: 105 | R9: =Q9*L9 -> 7875 | T9: NOVA UBIRATA | U9: 42652916000176 | V9: 75 | W9: 0
A10: 45880.352 | B10: 3973 | C10: AA AGRONEGOCIOS LTDA | D10: 45880 | E10: 46142 | F10: PEDRO FILIPE COELHO MAGALHAES | H10: 510200 | I10: VERDIVO COBRE EDTA 3 KG | J10: Verdivo | K10: KG | L10: 95 | M10: 5532 | N10: SAFRA 25/26 | O10: 72 | P10: 0 | Q10: 72 | R10: =Q10*L10 -> 6840 | T10: NOVA UBIRATA | U10: 42652916000176 | V10: 95 | W10: 0
A11: 45880.364 | B11: 3974 | C11: AA AGRONEGOCIOS LTDA | D11: 45880 | E11: 46142 | F11: PEDRO FILIPE COELHO MAGALHAES | G11: Sorriso | H11: 510200 | I11: LALRISE AZOS - AZ39 3L | J11: Lallemand | K11: LT | L11: 49.5 | M11: 5535 | N11: SAFRA 25/26 | O11: 72 | P11: 0 | Q11: 72 | R11: =Q11*L11 -> 3564 | T11: NOVA UBIRATA | U11: 42652916000176 | V11: 49.5 | W11: 0
A12: 45880.364 | B12: 3974 | C12: AA AGRONEGOCIOS LTDA | D12: 45880 | E12: 46142 | F12: PEDRO FILIPE COELHO MAGALHAES | G12: Sorriso | H12: 510200 | I12: RIZOS OG - 1 LT | J12: Lallemand | K12: LT | L12: 321 | M12: 5535 | N12: SAFRA 25/26 | O12: 35 | P12: 0 | Q12: 35 | R12: =Q12*L12 -> 11235 | T12: NOVA UBIRATA | U12: 42652916000176 | V12: 321 | W12: 0
A13: 45880.364 | B13: 3974 | C13: AA AGRONEGOCIOS LTDA | D13: 45880 | E13: 46142 | F13: PEDRO FILIPE COELHO MAGALHAES | G13: Sorriso | H13: 510200 | I13: ONIX OG - 1 LT | J13: Lallemand | K13: LT | L13: 311 | M13: 5535 | N13: SAFRA 25/26 | O13: 35 | P13: 0 | Q13: 35 | R13: =Q13*L13 -> 10885 | T13: NOVA UBIRATA | U13: 42652916000176 | V13: 311 | W13: 0
A14: 45880.364 | B14: 3974 | C14: AA AGRONEGOCIOS LTDA | D14: 45880 | E14: 46142 | F14: PEDRO FILIPE COELHO MAGALHAES | H14: 510200 | I14: VERDIVO STAND 5 LT | J14: Verdivo | K14: LT | L14: 220 | M14: 5535 | N14: SAFRA 25/26 | O14: 70 | P14: 0 | Q14: 70 | R14: =Q14*L14 -> 15400 | T14: NOVA UBIRATA | U14: 42652916000176 | V14: 220 | W14: 0
A15: 45880.364 | B15: 3974 | C15: AA AGRONEGOCIOS LTDA | D15: 45880 | E15: 46142 | F15: PEDRO FILIPE COELHO MAGALHAES | G15: Sorriso | H15: 510200 | I15: INOCULANTE STARFIX SOJA - 3 LT 1X10E10 UFC/ML | J15: Lallemand | K15: LT | L15: 50 | M15: 5535 | N15: SAFRA 25/26 | O15: 72 | P15: 0 | Q15: 72 | R15: =Q15*L15 -> 3600 | T15: NOVA UBIRATA | U15: 42652916000176 | V15: 50 | W15: 0
A16: 45880.364 | B16: 3974 | C16: AA AGRONEGOCIOS LTDA | D16: 45880 | E16: 46142 | F16: PEDRO FILIPE COELHO MAGALHAES | G16: Sorriso | H16: 510200 | I16: QUALITY WG - 1 KG | J16: Lallemand | K16: KG | L16: 385 | M16: 5535 | N16: SAFRA 25/26 | O16: 35 | P16: 0 | Q16: 35 | R16: =Q16*L16 -> 13475 | T16: NOVA UBIRATA | U16: 42652916000176 | V16: 385 | W16: 0
A17: 45880.374 | B17: 3975 | C17: AA AGRONEGOCIOS LTDA | D17: 45880 | E17: 46295 | F17: PEDRO FILIPE COELHO MAGALHAES | G17: Sorriso | H17: 510200 | I17: QUALITY WG - 1 KG | J17: Lallemand | K17: KG | L17: 385 | M17: 5534 | N17: SAFRINHA 2026 | O17: 28 | P17: 0 | Q17: 28 | R17: =Q17*L17 -> 10780 | T17: NOVA UBIRATA | U17: 42652916000176 | V17: 385 | W17: 0
A18: 45880.374 | B18: 3975 | C18: AA AGRONEGOCIOS LTDA | D18: 45880 | E18: 46295 | F18: PEDRO FILIPE COELHO MAGALHAES | H18: 510200 | I18: VERDIVO MN ACTION 20 LT | J18: Verdivo | K18: LT | L18: 18 | M18: 5534 | N18: SAFRINHA 2026 | O18: 700 | P18: 0 | Q18: 700 | R18: =Q18*L18 -> 12600 | T18: NOVA UBIRATA | U18: 42652916000176 | V18: 18 | W18: 0
A19: 45880.374 | B19: 3975 | C19: AA AGRONEGOCIOS LTDA | D19: 45880 | E19: 46295 | F19: PEDRO FILIPE COELHO MAGALHAES | G19: Sorriso | H19: 510200 | I19: RIZOS OG - 1 LT | J19: Lallemand | K19: LT | L19: 311 | M19: 5534 | N19: SAFRINHA 2026 | O19: 14 | P19: 0 | Q19: 14 | R19: =Q19*L19 -> 4354 | T19: NOVA UBIRATA | U19: 42652916000176 | V19: 311 | W19: 0
A20: 45880.374 | B20: 3975 | C20: AA AGRONEGOCIOS LTDA | D20: 45880 | E20: 46295 | F20: PEDRO FILIPE COELHO MAGALHAES | H20: 510200 | I20: VERDIVO VERDMAX 20L | J20: Verdivo | K20: LT | L20: 25 | M20: 5534 | N20: SAFRINHA 2026 | O20: 700 | P20: 0 | Q20: 700 | R20: =Q20*L20 -> 17500 | T20: NOVA UBIRATA | U20: 42652916000176 | V20: 25 | W20: 0
A21: 45880.374 | B21: 3975 | C21: AA AGRONEGOCIOS LTDA | D21: 45880 | E21: 46295 | F21: PEDRO FILIPE COELHO MAGALHAES | H21: 510200 | I21: VERDIVO PRODUTIVO MZ 10 KG | J21: Verdivo | K21: KG | L21: 23.5 | M21: 5534 | N21: SAFRINHA 2026 | O21: 1410 | P21: 0 | Q21: 1410 | R21: =Q21*L21 -> 33135 | T21: NOVA UBIRATA | U21: 42652916000176 | V21: 23.5 | W21: 0
A22: 45880.374 | B22: 3975 | C22: AA AGRONEGOCIOS LTDA | D22: 45880 | E22: 46295 | F22: PEDRO FILIPE COELHO MAGALHAES | H22: 510200 | I22: VERDIVO ATTACK SPRAY 5 LT | J22: Verdivo | K22: LT | L22: 75 | M22: 5534 | N22: SAFRINHA 2026 | O22: 60 | P22: 0 | Q22: 60 | R22: =Q22*L22 -> 4500 | T22: NOVA UBIRATA | U22: 42652916000176 | V22: 75 | W22: 0
A23: 45880.374 | B23: 3975 | C23: AA AGRONEGOCIOS LTDA | D23: 45880 | E23: 46295 | F23: PEDRO FILIPE COELHO MAGALHAES | G23: Sorriso | H23: 510200 | I23: ONIX OG - 1 LT | J23: Lallemand | K23: LT | L23: 321 | M23: 5534 | N23: SAFRINHA 2026 | O23: 14 | P23: 0 | Q23: 14 | R23: =Q23*L23 -> 4494 | T23: NOVA UBIRATA | U23: 42652916000176 | V23: 321 | W23: 0
A24: 45880.374 | B24: 3975 | C24: AA AGRONEGOCIOS LTDA | D24: 45880 | E24: 46295 | F24: PEDRO FILIPE COELHO MAGALHAES | G24: Sorriso | H24: 510200 | I24: LALRISE AZOS - AZ39 3L | J24: Lallemand | K24: LT | L24: 49.5 | M24: 5534 | N24: SAFRINHA 2026 | O24: 72 | P24: 0 | Q24: 72 | R24: =Q24*L24 -> 3564 | T24: NOVA UBIRATA | U24: 42652916000176 | V24: 49.5 | W24: 0
A25: 45880.374 | B25: 3975 | C25: AA AGRONEGOCIOS LTDA | D25: 45880 | E25: 46295 | F25: PEDRO FILIPE COELHO MAGALHAES | H25: 510200 | I25: VERDIVO STAND 5 LT | J25: Verdivo | K25: LT | L25: 220 | M25: 5534 | N25: SAFRINHA 2026 | O25: 70 | P25: 0 | Q25: 70 | R25: =Q25*L25 -> 15400 | T25: NOVA UBIRATA | U25: 42652916000176 | V25: 220 | W25: 0
A26: 45880.374 | B26: 3975 | C26: AA AGRONEGOCIOS LTDA | D26: 45880 | E26: 46295 | F26: PEDRO FILIPE COELHO MAGALHAES | H26: 510200 | I26: VERDIVO EXACT 5 LT | J26: Verdivo | K26: LT | L26: 75 | M26: 5534 | N26: SAFRINHA 2026 | O26: 140 | P26: 0 | Q26: 140 | R26: =Q26*L26 -> 10500 | T26: NOVA UBIRATA | U26: 42652916000176 | V26: 75 | W26: 0
A27: 45880.374 | B27: 3975 | C27: AA AGRONEGOCIOS LTDA | D27: 45880 | E27: 46295 | F27: PEDRO FILIPE COELHO MAGALHAES | H27: 510200 | I27: VERDIVO FIX COMONI 20 LT | J27: Verdivo | K27: LT | L27: 160 | M27: 5534 | N27: SAFRINHA 2026 | O27: 220 | P27: 0 | Q27: 220 | R27: =Q27*L27 -> 35200 | T27: NOVA UBIRATA | U27: 42652916000176 | V27: 160 | W27: 0
A28: 45972.573 | B28: 4257 | C28: AA AGRONEGOCIOS LTDA | D28: 45972 | E28: 46142 | F28: PEDRO FILIPE COELHO MAGALHAES | H28: 510200 | I28: VERDIVO VERDMAX 20L | J28: Verdivo | K28: LT | L28: 25 | M28: 5808 | N28: SAFRA 25/26 | O28: 100 | P28: 0 | Q28: 100 | R28: =Q28*L28 -> 2500 | T28: NOVA UBIRATA | U28: 42652916000176 | V28: 25 | W28: 0
A29: 45975.378 | B29: 4270 | C29: AA AGRONEGOCIOS LTDA | D29: 45975 | E29: 46142 | F29: PEDRO FILIPE COELHO MAGALHAES | H29: 510200 | I29: VERDIVO VERDMAX 20L | J29: Verdivo | K29: LT | L29: 25 | M29: 5814 | N29: SAFRA 25/26 | O29: 100 | P29: 0 | Q29: 100 | R29: =Q29*L29 -> 2500 | T29: NOVA UBIRATA | U29: 42652916000176 | V29: 25 | W29: 0
A30: 46043.711 | B30: 4480 | C30: AA AGRONEGOCIOS LTDA | D30: 46043 | E30: 46295 | F30: PEDRO FILIPE COELHO MAGALHAES | H30: 510200 | I30: VERDIVO BOROFORCE - 10 KG | J30: Verdivo | K30: KG | L30: 26.5 | M30: 6027 | N30: SAFRINHA 2026 | O30: 1800 | P30: 0 | Q30: 1800 | R30: =Q30*L30 -> 47700 | T30: NOVA UBIRATA | U30: 42652916000176 | V30: 26.5 | W30: 0
A31: 46076.41 | B31: 4600 | C31: AA AGRONEGOCIOS LTDA | D31: 46076 | E31: 46295 | F31: PEDRO FILIPE COELHO MAGALHAES | H31: 510200 | I31: VERDIVO STAND 5 LT | J31: Verdivo | K31: LT | L31: 220 | M31: 6098 | N31: SAFRINHA 2026 | O31: 5 | P31: 0 | Q31: 5 | R31: =Q31*L31 -> 1100 | T31: NOVA UBIRATA | U31: 42652916000176 | V31: 220 | W31: 0
A32: 45943.39 | B32: 343 | C32: ADELIR ANTONIO STRAPAZZON | D32: 45943 | E32: 46111 | F32: LUCAS NADAL ANGELI | H32: 510200 | I32: FORTGREEN INVICTUS 1 LT | K32: LT | L32: 165 | M32: 83 | N32: SAFRA 25/26 | O32: 10 | P32: 0 | Q32: 10 | R32: =Q32*L32 -> 1650 | T32: MARCELANDIA | U32: 78405963987 | V32: 165 | W32: 0
A33: 45943.39 | B33: 343 | C33: ADELIR ANTONIO STRAPAZZON | D33: 45943 | E33: 46111 | F33: LUCAS NADAL ANGELI | H33: 510200 | I33: ADJUVANTE PROTANK RESOLVE 1 KG | K33: KG | L33: 80 | M33: 83 | N33: SAFRA 25/26 | O33: 10 | P33: 0 | Q33: 10 | R33: =Q33*L33 -> 800 | T33: MARCELANDIA | U33: 78405963987 | V33: 80 | W33: 0
A34: 45848.59 | B34: 245 | C34: ADILSON FRANCISCO FISTAROL | D34: 45848 | E34: 46142 | F34: LUCAS NADAL ANGELI | G34: Sinop | H34: 510200 | I34: INOCULANTE LALFIX NITRO - 3 LT 1X10E10 UFC/ML | J34: Lallemand | K34: LT | L34: 36 | M34: 9 | N34: SAFRA 25/26 | O34: 1950 | P34: 0 | Q34: 1950 | R34: =Q34*L34 -> 70200 | T34: MARCELANDIA | U34: 32524897168 | V34: 36 | W34: 0
A35: 45848.59 | B35: 245 | C35: ADILSON FRANCISCO FISTAROL | D35: 45848 | E35: 46142 | F35: LUCAS NADAL ANGELI | G35: Sinop | H35: 510200 | I35: LALRISE AZOS - AZ39 3L | J35: Lallemand | K35: LT | L35: 40 | M35: 9 | N35: SAFRA 25/26 | O35: 1302 | P35: 0 | Q35: 1302 | R35: =Q35*L35 -> 52080 | T35: MARCELANDIA | U35: 32524897168 | V35: 40 | W35: 0
A36: 45848.59 | B36: 245 | C36: ADILSON FRANCISCO FISTAROL | D36: 45848 | E36: 46142 | F36: LUCAS NADAL ANGELI | G36: Sinop | H36: 510200 | I36: INOCULANTE STARFIX SOJA - 3 LT 1X10E10 UFC/ML | J36: Lallemand | K36: LT | L36: 36 | M36: 9 | N36: SAFRA 25/26 | O36: 1950 | P36: 0 | Q36: 1950 | R36: =Q36*L36 -> 70200 | T36: MARCELANDIA | U36: 32524897168 | V36: 36 | W36: 0
A37: 45848.59 | B37: 245 | C37: ADILSON FRANCISCO FISTAROL | D37: 45848 | E37: 46142 | F37: LUCAS NADAL ANGELI | G37: Sinop | H37: 510200 | I37: QUALITY WG - 1 KG | J37: Lallemand | K37: KG | L37: 360 | M37: 9 | N37: SAFRA 25/26 | O37: 650 | P37: 0 | Q37: 650 | R37: =Q37*L37 -> 234000 | T37: MARCELANDIA | U37: 32524897168 | V37: 360 | W37: 0
A38: 45848.59 | B38: 245 | C38: ADILSON FRANCISCO FISTAROL | D38: 45848 | E38: 46142 | F38: LUCAS NADAL ANGELI | H38: 510200 | I38: VERDIVO EXACT 5 LT | J38: Verdivo | K38: LT | L38: 65 | M38: 9 | N38: SAFRA 25/26 | O38: 1000 | P38: 0 | Q38: 1000 | R38: =Q38*L38 -> 65000 | T38: MARCELANDIA | U38: 32524897168 | V38: 65 | W38: 0
A39: 45848.59 | B39: 245 | C39: ADILSON FRANCISCO FISTAROL | D39: 45848 | E39: 46142 | F39: LUCAS NADAL ANGELI | G39: Sinop | H39: 510200 | I39: ONIX OG - 1 LT | J39: Lallemand | K39: LT | L39: 260 | M39: 9 | N39: SAFRA 25/26 | O39: 650 | P39: 0 | Q39: 650 | R39: =Q39*L39 -> 169000 | T39: MARCELANDIA | U39: 32524897168 | V39: 260 | W39: 0
A40: 45848.59 | B40: 245 | C40: ADILSON FRANCISCO FISTAROL | D40: 45848 | E40: 46142 | F40: LUCAS NADAL ANGELI | G40: Sinop | H40: 510200 | I40: RIZOS OG - 1 LT | J40: Lallemand | K40: LT | L40: 260 | M40: 9 | N40: SAFRA 25/26 | O40: 650 | P40: 0 | Q40: 650 | R40: =Q40*L40 -> 169000 | T40: MARCELANDIA | U40: 32524897168 | V40: 260 | W40: 0
...
